<?xml version="1.0"?>
<robot name="simple_serial_robot">

  <material name="blue">
    <color rgba="0 0.1 0.6 1"/>
  </material>
  <material name="dark_blue">
    <color rgba="0 0 0.4 1"/>
  </material>
  <material name="black">
    <color rgba="0 0 0 1"/>
  </material>
  <material name="white">
    <color rgba="1 1 1 1"/>
  </material>

  

  <link name="base_link">
    <visual>
      <geometry>
        <box size="0.6 0.6 0.01" />
      </geometry>
      <origin xyz="0 0 0"/>
      <material name="black"/>
    </visual>
  </link>

  <link name="arm_base">
    <visual>
      <geometry>
        <box size="0.11 0.15 0.35" />
      </geometry>
      <origin xyz="0 0 0.175"/>
      <material name="dark_blue"/>
    </visual>
  </link>

  <!-- change previous joint so it moves around the z axis instead-->
  <joint name="joint1" type="revolute">
    <parent link="base_link"/>
    <child link="arm_base"/>
    <origin xyz="0 0 0"/>
    <axis xyz="0 0 1"/>
    <limit lower="-3.14" upper="3.14" effort="1000.0" velocity="0.5"/>
  </joint>

  <link name="link1">
    <visual>
      <geometry>
        <box size="0.1 0.1 0.4"/>
      </geometry>
      <origin xyz="0 0 0.2"/>
      <material name="blue"/>
    </visual>
  </link>

  <joint name="joint2" type="revolute">
    <parent link="arm_base"/>
    <child link="link1"/>
    <origin xyz="0 0 0.35"/>
    <limit lower="-1.57" upper="1.57" effort="1000.0" velocity="0.5"/>
  </joint>

  <link name="link2">
    <visual>
      <geometry>
        <box size="0.05 0.05 0.2"/>
      </geometry>
      <origin xyz="0 0 0.1"/>
      <material name="white"/>
    </visual>
  </link>

  <joint name="joint3" type="revolute">
    <parent link="link1"/>
    <child link="link2"/>
    <origin xyz="0 0 0.4"/>
    <limit lower="-1.57" upper="1.57" effort="1000.0" velocity="0.5"/>
  </joint>
  
  <link name="link_eef">
    <visual>
      <geometry>
        <sphere radius="0.05"/>
      </geometry>
      <origin xyz="0 0 0"/>
      <material name="black"/>
    </visual>
  </link>

  <joint name="joint_eef" type="fixed">
    <parent link="link2"/>
    <child link="link_eef"/>
    <origin xyz="0 0 0.2"/>
  </joint>
  
</robot>