<?xml version="1.0"?>
<robot name="simple_serial_robot">

  <material name="blue">
    <color rgba="0 0 0.8 1"/>
  </material>
  <material name="black">
    <color rgba="0 0 0 1"/>
  </material>
  <material name="white">
    <color rgba="1 1 1 1"/>
  </material>

  <link name="base_link">
    <visual>
      <geometry>
        <box size="0.0 0.0 0.0"/>
      </geometry>
      <material name="blue"/>
    </visual>
  </link>

  <link name="arm_base">
    <visual>
      <geometry>
        <cylinder radius="0.25" length="0.05" />
      </geometry>
      <material name="black"/>
    </visual>
  </link>

  <!-- change previous joint so it moves around the z axis instead-->
  <joint name="joint1" type="revolute">
    <parent link="base_link"/>
    <child link="arm_base"/>
    <origin xyz="0 0 0.025"/>
    <axis xyz="0 0 1"/>
    <limit lower="-3.14" upper="3.14" effort="1000.0" velocity="0.5"/>
  </joint>

  <link name="link1">
    <visual>
      <geometry>
        <box size="0.1 0.1 0.4"/>
      </geometry>
      <origin xyz="0 0 0.16"/>
      <material name="blue"/>
    </visual>
  </link>

  <joint name="joint2" type="revolute">
    <parent link="arm_base"/>
    <child link="link1"/>
    <origin xyz="0.0 0 0.05"/>
    <limit lower="-3.14" upper="3.14" effort="1000.0" velocity="0.5"/>
  </joint>

  <link name="link2">
    <visual>
      <geometry>
        <box size="0.1 0.1 0.4"/>
      </geometry>
      <origin xyz="0 0 0.16"/>
      <material name="white"/>
    </visual>
  </link>

  <joint name="joint3" type="revolute">
    <parent link="link1"/>
    <child link="link2"/>
    <origin xyz="0 0 0.4"/>
    <limit lower="-3.14" upper="3.14" effort="1000.0" velocity="0.5"/>
  </joint>



</robot>