<?xml version="1.0"?>
<robot name="simple_serial_robot">

  <material name="blue">
    <color rgba="0 0 0.8 1"/>
  </material>
  <material name="black">
    <color rgba="0 0 0 1"/>
  </material>
  <material name="white">
    <color rgba="1 1 1 1"/>
  </material>

  <link name="base_link">
    <visual>
      <geometry>
        <box size="0.6 0.6 0.01" />
      </geometry>
      <origin xyz="0 0 0"/>
      <material name="black"/>
    </visual>
  </link>

  <link name="U_arm_base">
    <visual>
      <geometry>
        <box size="0.1 0.1 0.01" />
      </geometry>
      <origin xyz="0 0 0"/>
      <material name="white"/>
    </visual>
  </link>

  <!-- change previous joint so it moves around the z axis instead-->
  <joint name="U_joint1" type="revolute">
    <parent link="base_link"/>
    <child link="U_arm_base"/>
    <origin xyz="0 0.25 0.025"/>
    <axis xyz="0 0 1"/>
    <limit lower="-3.14" upper="3.14" effort="1000.0" velocity="0.5"/>
  </joint>

  <link name="U_link1">
    <visual>
      <geometry>
        <box size="0.1 0.1 0.4"/>
      </geometry>
      <origin xyz="0 0 0.16"/>
      <material name="blue"/>
    </visual>
  </link>

  <joint name="U_joint2" type="revolute">
    <parent link="U_arm_base"/>
    <child link="U_link1"/>
    <origin xyz="0.0 0 0.05"/>
    <limit lower="-1.57" upper="1.57" effort="1000.0" velocity="0.5"/>
  </joint>

  <link name="U_link2">
    <visual>
      <geometry>
        <box size="0.1 0.1 0.4"/>
      </geometry>
      <origin xyz="0 0 0.16"/>
      <material name="white"/>
    </visual>
  </link>

  <joint name="U_joint3" type="revolute">
    <parent link="U_link1"/>
    <child link="U_link2"/>
    <origin xyz="0 0 0.4"/>
    <limit lower="-1.57" upper="1.57" effort="1000.0" velocity="0.5"/>
  </joint>

  <link name="L_arm_base">
    <visual>
      <geometry>
        <box size="0.1 0.1 0.01" />
      </geometry>
      <origin xyz="0 0 0"/>
      <material name="white"/>
    </visual>+
  </link>

  <!-- change previous joint so it moves around the z axis instead-->
  <joint name="L_joint1" type="revolute">
    <parent link="base_link"/>
    <child link="L_arm_base"/>
    <origin xyz="0.12 -0.25 0.025"/>
    <axis xyz="0 0 1"/>
    <limit lower="-3.14" upper="3.14" effort="1000.0" velocity="0.5"/>
  </joint>

  <link name="L_link1">
    <visual>
      <geometry>
        <box size="0.1 0.1 0.4"/>
      </geometry>
      <origin xyz="0 0 0.16"/>
      <material name="blue"/>
    </visual>
  </link>

  <joint name="L_joint2" type="revolute">
    <parent link="L_arm_base"/>
    <child link="L_link1"/>
    <origin xyz="0.0 0 0.05"/>
    <limit lower="-1.57" upper="1.57" effort="1000.0" velocity="0.5"/>
  </joint>

  <link name="L_link2">
    <visual>
      <geometry>
        <box size="0.1 0.1 0.4"/>
      </geometry>
      <origin xyz="0 0 0.16"/>
      <material name="white"/>
    </visual>
  </link>

  <joint name="L_joint3" type="revolute">
    <parent link="L_link1"/>
    <child link="L_link2"/>
    <origin xyz="0 0 0.4"/>
    <limit lower="-1.57" upper="1.57" effort="1000.0" velocity="0.5"/>
  </joint>

  <link name="R_arm_base">
    <visual>
      <geometry>
        <box size="0.1 0.1 0.01" />
      </geometry>
      <origin xyz="0 0 0"/>
      <material name="white"/>
    </visual>
  </link>

  <!-- change previous joint so it moves around the z axis instead-->
  <joint name="R_joint1" type="revolute">
    <parent link="base_link"/>
    <child link="R_arm_base"/>
    <origin xyz="-0.12 -0.25 0.025"/>
    <axis xyz="0 0 1"/>
    <limit lower="-3.14" upper="3.14" effort="1000.0" velocity="0.5"/>
  </joint>

  <link name="R_link1">
    <visual>
      <geometry>
        <box size="0.1 0.1 0.4"/>
      </geometry>
      <origin xyz="0 0 0.16"/>
      <material name="blue"/>
    </visual>
  </link>

  <joint name="R_joint2" type="revolute">
    <parent link="R_arm_base"/>
    <child link="R_link1"/>
    <origin xyz="0.0 0 0.05"/>
    <limit lower="-1.57" upper="1.57" effort="1000.0" velocity="0.5"/>
  </joint>

  <link name="R_link2">
    <visual>
      <geometry>
        <box size="0.1 0.1 0.4"/>
      </geometry>
      <origin xyz="0 0 0.16"/>
      <material name="white"/>
    </visual>
  </link>

  <joint name="R_joint3" type="revolute">
    <parent link="R_link1"/>
    <child link="R_link2"/>
    <origin xyz="0 0 0.4"/>
    <limit lower="-1.57" upper="1.57" effort="1000.0" velocity="0.5"/>
  </joint>
  
</robot>